Workbook

Sheet Inputs
B1: dont touch: | C1: user input | D1: calculated
A2: log bugs on our JIRA board -> | B2: https://imec.atlassian.net/jira/software/c/projects/AM/boards/222?quickFilter=822
A3: Create -> type: Bug, label: analytical_modeling
A4: Neural network training parameters | B4: config in calculated row: | C4: 128T
A5: Parameter | B5: Weight precision (bits) | C5: Activation precision (bits) | D5: gradient precision (bits) | E5: Batch size [B] | F5: minibatch size [mb] | G5: microbatch size [ub] | H5: sequence length aka context [s] | I5: hidden layer dimension for attention sublayers [h] | J5: hidden layer dimension for the 1st MLP sublayer [h_MLP1] | K5: hidden layer dimension for the 2nd MLP sublayer [h_MLP2] | L5: activations volume per layer per batch [N_act] | M5: number of batches [N_batch] | N5: number of layers [N_L] | O5: number of tokens to train | P5: number of sequences to train aka samples | Q5: number of attention heads | R5: dimensionality | S5: Query MAC operations | T5: Key MAC operations | U5: Value MAC operations | V5: self-attention MAC operations | W5: Multihead MAC operations | X5: Attention sublayer output MAC operations | Y5: total attention sublayer MAC operations | Z5: total MLP sublayer MAC operations | AA5: non linear operations for attention sublayer | AB5: non linear operations for MLP sublayer | AC5: error volume per layer per batch [N_err] | AD5: Dim Query weight (Wq) | AE5: Dim key weight (Wk) | AF5: Dim value weight (Wv) | AG5: projection weight (Wo) | AH5: feedforward bias1 | AI5: feedforward bias2 | AJ5: feedforward scale 1 | AK5: feedforward scale 2 | AL5: Number of parameters per layer | AM5: Number of parameters per Expert | AN5: Optimizer state precision | AO5: No. of MoE Layers | AP5: Expert Flag | AQ5: No of Experts | AR5: No of Gating parameters | AS5: No of Expert parameters | AT5: Gating MAC operations | AU5: Total number of parameters without embedding | AV5: Key/Query/Value length | AW5: ntokens in vocabulary | AX5: embedding layer parameters | AY5: Corrected Total no of Parametrrs (+ Decoder) | AZ5: Decoder NMACs | BA5: Decoder FLAG
A6: use calculation or override with user input | B6: user input | C6: user input | D6: user input | E6: user input | F6: calculated | G6: calculated | H6: calculated | I6: calculated | J6: calculated | K6: calculated | L6: calculated | M6: calculated | N6: calculated | O6: calculated | P6: calculated | Q6: calculated | R6: calculated | S6: calculated | T6: calculated | U6: calculated | V6: calculated | W6: calculated | X6: calculated | Y6: calculated | Z6: calculated | AA6: calculated | AB6: calculated | AC6: calculated | AD6: calculated | AE6: calculated | AF6: calculated | AG6: calculated | AH6: calculated | AI6: calculated | AJ6: calculated | AK6: calculated | AL6: calculated | AM6: calculated | AN6: user input | AO6: calculated | AP6: calculated | AQ6: calculated | AR6: calculated | AS6: calculated | AT6: calculated | AU6: calculated | AV6: calculated | AW6: calculated | AX6: calculated | AY6: calculated | AZ6: calculated | BA6: user input
A7: Value used in formula | B7: =IF(B6=$C$1,B8,B9) -> 16 | C7: =IF(C6=$C$1,C8,C9) -> 16 | D7: =IF(D6=$C$1,D8,D9) -> 32 | E7: =IF(E6=$C$1,E8,E9) -> 5120 | F7: =IF(F6=$C$1,F8,F9) -> 5120 | G7: =IF(G6=$C$1,G8,G9) -> 5120 | H7: =IF(H6=$C$1,H8,H9) -> 8192 | I7: =IF(I6=$C$1,I8,I9) -> 77.333333 | ... BA7: =IF(BA6=$C$1,BA8,BA9) -> 1
A8: user input value | B8: 16 | C8: 16 | D8: 32 | E8: 5120 | H8: 5 | I8: 64 | J8: 512 | K8: 64 | M8: 12288 | N8: 16 | O8: 2049990 | P8: 2049990 | Q8: 8 | R8: 1024 | AN8: 32 | AO8: 0 | AQ8: 96 | AV8: 64 | AW8: 28782 | AX8: 50257 | AY8: 50257 | AZ8: 50257 | BA8: 1
A9: Calculated from more detail or defined earlier | B9: N/A | C9: N/A | D9: N/A | E9: 5120 | F9: =E7/J14 -> 5120 | G9: =F7/B14 -> 5120 | H9: =VLOOKUP($C$4,Network[#All],4,FALSE) -> 8192 | I9: =VLOOKUP($C$4,Network[#All],7,FALSE) -> 77.333333 | J9: =R7 -> 37120 | K9: =VLOOKUP($C$4,Network[#All],9,FALSE) -> 148480 | L9: =E7*H7*I7 -> 3.2435951e+09 | M9: =P7/E7 -> 7152557.4 | N9: =VLOOKUP($C$4,Network[#All],5,FALSE) -> 480 | O9: =VLOOKUP($C$4,Network[#All],10,FALSE) -> 300000000000000 | P9: =O7/H7 -> 36621093750 | Q9: =VLOOKUP($C$4,Network[#All],6,FALSE) -> 480 | R9: =VLOOKUP($C$4,Network[#All],3,FALSE) -> 37120 | S9: =E7*R7*I7*H7 -> 1.2040225e+14 | T9: =E7*R7*I7*H7 -> 1.2040225e+14 | U9: =E7*R7*I7*H7 -> 1.2040225e+14 | V9: =2*E7*H7*H7*I7 -> 5.3143062e+13 | W9: =(S9+T9+U9+V9)*Q7 -> 1.9888791e+17 | X9: =E7*H7*R7*R7 -> 5.779308e+16 | Y9: =W9+X9 -> 2.5668099e+17 | Z9: =E7*H7*J7*K7*2 -> 4.6234464e+17 | AA9: =E7*H7*I7*Q7 -> 1.5569256e+12 | AB9: =2*E7*(J7+K7) -> 1900544000 | AC9: =E7*H7*I7 -> 3.2435951e+09 | AD9: =R7 -> 37120 | AE9: =R7 -> 37120 | AF9: =R7 -> 37120 | AG9: =R7 -> 37120 | AH9: =R7 -> 37120 | AI9: =R7 -> 37120 | AJ9: =R7 -> 37120 | AK9: =R7 -> 37120 | AL9: =(AD7*AV7*Q7 + AE7*AV7*Q7 + AF7*AV7*Q7+AG7*AV7*Q7+AH7+AI7+AJ7+AK7+2*K7*J7)+AX7/N7 -> 1.6538841e+10 | AM9: =AL7*N7 -> 7938643558400 | AN9: N/A | AO9: =N7/2 -> 240 | AP9: =INT(AQ7>1) -> 0 | AQ9: =VLOOKUP($C$4,Network[#All],11,FALSE) -> 1 | AR9: =AP7*R7*AQ7*AO7 -> 0 | AS9: =(AQ7-1)*AO7*2*(J7*K7) -> 0 | AT9: =H7*(R7-1)*E7*AP7*AQ7*AO7 -> 0 | AU9: =(AL7*N7)+AR7+AS7 -> 7938643558400 | AV9: =VLOOKUP($C$4,Network[#All],7,FALSE) -> 77.333333 | AW9: =VLOOKUP($C$4,Network[#All],2,FALSE) -> 51200 | AX9: =AW7*R7 -> 1900544000 | AY9: =2*AX9+AU9 -> 7942444646400 | AZ9: =E7*AW7*R7*BA7 -> 9730785280000 | BA9: =F7*AX7*S7 -> 1.1716084e+27
A10: comments | N10: Put 3E11 in O8 | O10: No of tokens (O9) goes up by 3 orders of magnitidue for MoE models
A11: Mapping parameters
A12: Parameter | B12: number of microbatches per minibatch [N_ubatch] | C12: intra node Data parallel degree [N_DP_intra] | D12: intra node Tensor parallel degree [N_TP_intra] | E12: intra node Pipeline parallel degree [N_PP_intra] | F12: accelerators per node required [R_acc_node] | G12: inter node Data parallel degree [N_DP_inter] | H12: inter node Tensor parallel degree [N_TP_inter] | I12: inter node Pipeline parallel degree [N_PP_inter] | J12: Data parallel degree [N_DP] | K12: Tensor parallel degree [N_TP] | L12: Pipeline parallel degree [N_PP] | M12: Number of accelerators required [R_acc_total] | N12: Number of nodes required [R_nodes_total] | O12: Required memory per accelerator due to weights (in GB) | P12: Required memory per accelerator due to activations (in GB) | Q12: Total memory required per accelerator in GB | R12: Min memory required per accelerator in GB | S12: Model memory for Training (GB) | T12: Model Memory for inference (GB) | U12: Memory per Acc (GB) | V12: Min acc required for inference | W12: Min acc required for training
A13: use calculation or override with user input | B13: calculated | C13: user input | D13: user input | E13: user input | F13: calculated | G13: user input | H13: user input | I13: user input | J13: calculated | K13: calculated | L13: calculated | M13: calculated | N13: calculated | O13: calculated | P13: calculated | Q13: calculated | R13: calculated | S13: calculated | T13: calculated | U13: calculated | V13: calculated | W13: calculated
A14: Value used in formula | B14: =IF(B13=$C$1,B15,B16) -> 1 | C14: =IF(C13=$C$1,C15,C16) -> 1 | D14: =IF(D13=$C$1,D15,D16) -> 1 | E14: =IF(E13=$C$1,E15,E16) -> 1 | F14: =IF(F13=$C$1,F15,F16) -> 1 | G14: =IF(G13=$C$1,G15,G16) -> 1 | H14: =IF(H13=$C$1,H15,H16) -> 1 | I14: =IF(I13=$C$1,I15,I16) -> 1 | ... W14: =IF(W13=$C$1,W15,W16) -> 20570
A15: user input value | B15: 1 | C15: 1 | D15: 1 | E15: 1 | G15: 1 | H15: 1 | I15: 1
A16: Calculated from more detail or defined earlier | B16: =L14 -> 1 | F16: =C14*D14*E14 -> 1 | J16: =C14*G14 -> 1 | K16: =D14*H14 -> 1 | L16: =E14*I14 -> 1 | M16: =J14*K14*L14 -> 1 | N16: =M14/F14 -> 1 | O16: =(B7 + D7 + 3*AN7)*AU7/(8*J14*K14*L14)/1000000000 -> 142895.58 | P16: =(C7*N7)*((AA7+AB7+2*AC7)/B14/J14)/(8*J14*K14*L14)/1000000000 -> 1502700.8 | Q16: =P16+O16 -> 1645596.4 | R16: =(B7 + D7/2)*AU7/(8*J14*K14*L14)/1000000000+P14 -> 1534455.4 | S16: =(((B7 + D7 + 3*AN7)*AU7)+((C7*N7)*((AA7+AB7+2*AC7))))/(8*1000000000) -> 1645596.4 | T16: =(B7 + D7 + 3*AN7)*AU7/(8)/1000000000 -> 142895.58 | U16: =T16/M16 -> 142895.58 | V16: =_xlfn.CEILING.MATH((T16/(N28/1000000000))) -> 1787 | W16: =_xlfn.CEILING.MATH((S16/(N28/1000000000))) -> 20570
A17: comments | B17: user input | K17: Nvlink | O17: from zero paper =[ (wt_prec+grad_prec+K)*¥ + b x Layers x Act_prec ]/(8*N_DP*N_PP*N_TP) + ub*act_prec, here 8 is used to convert to bytes, FOR mOe
A18: System architecture parameters
A19: Parameter | B19: Inter node latency (s) [C_inter] | C19: number of network cards per node | D19: bandwidth per network card (bits/s) | E19: Inter node bandwidth (bits/s) [BW_inter] | F19: inter node topology factor | G19: number of accelerators per node [N_acc_node] | H19: total intra node bandwidth | I19: intra node topology factor | J19: Number of nodes | K19: Total number of accelerators [N_acc_total]
A20: use calculation or override with user input | B20: user input | C20: user input | D20: calculated | E20: calculated | F20: user input | G20: user input | H20: calculated | I20: user input | J20: user input | K20: calculated
A21: Value used in formula | B21: =IF(B20=$C$1,B22,B23) -> 1e-07 | C21: =IF(C20=$C$1,C22,C23) -> 1 | D21: =IF(D20=$C$1,D22,D23) -> 40000000000000 | E21: =IF(E20=$C$1,E22,E23) -> 40000000000000 | F21: =IF(F20=$C$1,F22,F23) -> 0 | G21: =IF(G20=$C$1,G22,G23) -> 8 | H21: =IF(H20=$C$1,H22,H23) -> 1.6e+15 | I21: =IF(I20=$C$1,I22,I23) -> 0 | ... K21: =IF(K20=$C$1,K22,K23) -> 8
A22: user input value | B22: 1e-07 | C22: =F14 -> 1 | D22: 204800000000000 | G22: 8 | J22: 1
A23: Calculated from more detail or defined earlier | D23: =VLOOKUP($D$24,'Communication specs'!A2:B45,2,FALSE) -> 40000000000000 | E23: =C21*D21 -> 40000000000000 | H23: =M28*G21 -> 1.6e+15 | K23: =J21*G21 -> 8
A24: comments | B24: assume infiniband between nodes | D24: Optical OIO Taper-5 | F24: not used atm | I24: not used atm | J24: not used atm | K24: not used atm | L24: move this to accelerator specs tab
A25: Accelerator architecture parameters | B25: configuration in calculated row | C25: H100 SXM5
A26: Parameter | B26: frequency (cycles/s) [f] | C26: number of cores [N_cores] | D26: number of functional units per core [N_FU] | E26: functional unit hardware 8-bit MAC/cycle [W_FU] | F26: peak compute 8-bit MACs (MAC/s) | G26: OPS/MAC | H26: peak compute 8-bit (OPS/s) | I26: number of non-linear functional units per core | J26: non linear functional unit hardware 8-bit NLIN/cycle | K26: peak compute 8-bit non-linear function (NLIN/s) | L26: inter accelerator latency [C_intra] | M26: inter accelerator bandwidth (bits/s) [BW_intra] | N26: Memory capacity per accelerator (Bytes) | O26: Accelerator TDP | P26: Accelerator frequency at TDP (cycles/s)
A27: use calculation or override with user input | B27: calculated | C27: user input | D27: calculated | E27: calculated | F27: calculated | G27: user input | H27: calculated | I27: calculated | J27: calculated | K27: calculated | L27: calculated | M27: user input | N27: calculated | O27: calculated | P27: calculated
A28: Value used in formula | B28: =IF(B27=$C$1,B29,B30) -> 1800000000 | C28: =IF(C27=$C$1,C29,C30) -> 252 | D28: =IF(D27=$C$1,D29,D30) -> 4 | E28: =IF(E27=$C$1,E29,E30) -> 1024 | F28: =IF(F27=$C$1,F29,F30) -> 1.8579456e+15 | G28: =IF(G27=$C$1,G29,G30) -> 2 | H28: =IF(H27=$C$1,H29,H30) -> 3.7158912e+15 | I28: =IF(I27=$C$1,I29,I30) -> 320 | ... P28: =IF(P27=$C$1,P29,P30) -> 1800000000
A29: user input value | B29: 1410000000 | C29: 252 | D29: 4 | E29: 512 | G29: 2 | I29: =48*4 -> 192 | J29: 4 | L29: 1e-08 | M29: =M33 -> 200000000000000 | N29: 80000000000 | O29: 400
A30: Calculated from more detail or defined earlier | B30: =VLOOKUP($C$25,Accelerator[#All],2,FALSE) -> 1800000000 | C30: =VLOOKUP($C$25,Accelerator[#All],3,FALSE) -> 132 | D30: =VLOOKUP($C$25,Accelerator[#All],4,FALSE) -> 4 | E30: =VLOOKUP($C$25,Accelerator[#All],5,FALSE) -> 1024 | F30: =B28*C28*D28*E28 -> 1.8579456e+15 | H30: =F28*G28 -> 3.7158912e+15 | I30: =VLOOKUP($C$25,Accelerator[#All],6,FALSE) -> 320 | J30: =VLOOKUP($C$25,Accelerator[#All],7,FALSE) -> 4 | K30: =B28*C28*I28*J28 -> 580608000000000 | L30: =VLOOKUP($C$25,Accelerator[#All],8,FALSE) -> 1e-08 | M30: =VLOOKUP($C$25,Accelerator[#All],9,FALSE) -> 3600000000000 | N30: =VLOOKUP($C$25,Accelerator[#All],14,FALSE) -> 80000000000 | O30: =VLOOKUP($C$25,Accelerator[#All],10,FALSE) -> 700 | P30: =VLOOKUP($C$25,Accelerator[#All],2,FALSE) -> 1800000000
G31: people count 2 ops/MAC typically | M31: Optical OIO 25Tx8
A32: MoE Overhead
M33: =VLOOKUP($M$31,'Communication specs'!A2:B45,2,FALSE) -> 200000000000000

Sheet Transformer Network Parameters
F2: Main params | K2: Derived params by rules of thumb
E4: Network | F4: Tokens | G4: Dimensionality | H4: Context | I4: Layers | J4: Attention Heads | K4: query/key length | L4: value length | M4: hidden layer size | N4: Tokens to train | O4: Experts | P4: Compute cost FP16
B5: GPT-2: | C5: https://openai.com/blog/better-language-models/ | E5: min-GPT | F5: 65 | G5: 768 | H5: 128 | I5: 12 | J5: 12 | K5: =G5/J5 -> 64 | L5: =G5/J5 -> 64 | M5: =G5*4 -> 3072 | N5: 40000000000 | O5: 1
B6: GPT-2: | C6: https://openai.com/blog/better-language-models/ | E6: GPT-2 small | F6: 50257 | G6: 768 | H6: 1024 | I6: 12 | J6: 12 | K6: =G6/J6 -> 64 | L6: =G6/J6 -> 64 | M6: =G6*4 -> 3072 | N6: 40000000000 | O6: 1
B7: GPT-3: | C7: https://arxiv.org/abs/2005.14165 | E7: GPT-2 medium | F7: 50257 | G7: 1024 | H7: 1024 | I7: 24 | J7: 16 | K7: =G7/J7 -> 64 | L7: =G7/J7 -> 64 | M7: =G7*4 -> 4096 | N7: 40000000000 | O7: 1
B8: Megatron-LM | C8: https://github.com/NVIDIA/Megatron-LM | E8: GPT-2 large | F8: 50257 | G8: 1280 | H8: 1024 | I8: 36 | J8: 20 | K8: =G8/J8 -> 64 | L8: =G8/J8 -> 64 | M8: =G8*4 -> 5120 | N8: 40000000000 | O8: 1
E9: GPT-2 extralarge | F9: 50257 | G9: 1600 | H9: 1024 | I9: 48 | J9: 25 | K9: =G9/J9 -> 64 | L9: =G9/J9 -> 64 | M9: =G9*4 -> 6400 | N9: 40000000000 | O9: 1
E10: GPT-3 Small | F10: 50257 | G10: 768 | H10: 2048 | I10: 12 | J10: 12 | K10: =G10/J10 -> 64 | L10: =G10/J10 -> 64 | M10: =G10*4 -> 3072 | N10: 300000000000 | O10: 1
E11: GPT-3 Medium | F11: 50257 | G11: 1024 | H11: 2048 | I11: 24 | J11: 16 | K11: =G11/J11 -> 64 | L11: =G11/J11 -> 64 | M11: =G11*4 -> 4096 | N11: 300000000000 | O11: 1
E12: GPT-3 Large | F12: 50257 | G12: 1536 | H12: 2048 | I12: 24 | J12: 16 | K12: =G12/J12 -> 96 | L12: =G12/J12 -> 96 | M12: =G12*4 -> 6144 | N12: 300000000000 | O12: 1
E13: GPT-3 XL | F13: 50257 | G13: 2048 | H13: 2048 | I13: 24 | J13: 24 | K13: 80 | L13: 80 | M13: =G13*4 -> 8192 | N13: 300000000000 | O13: 1
E14: GPT-3 2.7B | F14: 50257 | G14: 2560 | H14: 2048 | I14: 32 | J14: 32 | K14: =G14/J14 -> 80 | L14: =G14/J14 -> 80 | M14: =G14*4 -> 10240 | N14: 300000000000 | O14: 1
E15: GPT-3 6.7 | F15: 50257 | G15: 4096 | H15: 2048 | I15: 32 | J15: 32 | K15: =G15/J15 -> 128 | L15: =G15/J15 -> 128 | M15: =G15*4 -> 16384 | N15: 300000000000 | O15: 1
E16: GPT-3 13B | F16: 50257 | G16: 5120 | H16: 2048 | I16: 40 | J16: 40 | K16: =G16/J16 -> 128 | L16: =G16/J16 -> 128 | M16: =G16*4 -> 20480 | N16: 300000000000 | O16: 1
E17: GPT-3 175B aka "GPT-3" | F17: 50257 | G17: 12288 | H17: 2048 | I17: 96 | J17: 96 | K17: =G17/J17 -> 128 | L17: =G17/J17 -> 128 | M17: =G17*4 -> 49152 | N17: 300000000000 | O17: 1 | P17: =3.14E+23 -> 3.14e+23 | R17: 300000000000
E18: Megatron 145B | F18: 51200 | G18: 12288 | H18: 2048 | I18: 80 | J18: 96 | K18: =G18/J18 -> 128 | L18: =G18/J18 -> 128 | M18: =G18*4 -> 49152 | N18: 300000000000 | O18: 1
E19: Megatron 310B | F19: 51200 | G19: 16384 | H19: 2048 | I19: 96 | J19: 128 | K19: =G19/J19 -> 128 | L19: =G19/J19 -> 128 | M19: =G19*4 -> 65536 | N19: 300000000000 | O19: 1
E20: Megatron 530B | F20: 51200 | G20: 20480 | H20: 2048 | I20: 105 | J20: 128 | K20: =G20/J20 -> 160 | L20: =G20/J20 -> 160 | M20: =G20*4 -> 81920 | N20: 300000000000 | O20: 1
E21: Megatron 1T | F21: 51200 | G21: 25600 | H21: 2048 | I21: 128 | J21: 160 | K21: =G21/J21 -> 160 | L21: =G21/J21 -> 160 | M21: =G21*4 -> 102400 | N21: 300000000000 | O21: 1
E22: QPM | F22: 51200 | G22: =(256+128)*1024 -> 393216 | H22: =8*1024 -> 8192 | I22: =512+256 -> 768 | J22: =1024+512 -> 1536 | K22: =G22/J22 -> 256 | L22: =G22/J22 -> 256 | M22: =G22*4 -> 1572864 | N22: =(1420000000000000/175000000000000)^0.74*N17 -> 1.4124285e+12 | O22: 1
E23: DeepNet/OPUS-100 | F23: 50257 | G23: 512 | H23: 128 | I23: 1000 | J23: 8 | K23: =G23/J23 -> 64 | L23: =G23/J23 -> 64 | M23: =G23*4 -> 2048 | N23: 40000000000 | O23: 1
E24: DeepNet/M2M | F24: 50257 | G24: 1024 | H24: 256 | I24: 200 | J24: 16 | K24: =G24/J24 -> 64 | L24: =G24/J24 -> 64 | M24: =G24*4 -> 4096 | N24: 40000000000 | O24: 1
E25: DeepNet/QPM | F25: 51200 | G25: 12288 | H25: 2048 | I25: =1024*512 -> 524288 | J25: 96 | K25: =G25/J25 -> 128 | L25: =G25/J25 -> 128 | M25: =G25*4 -> 49152 | N25: =(1420000000000000/175000000000000)^0.74*N20 -> 1.4124285e+12 | O25: 1
A26: Hidden | B26: Attention size | C26: Blocks | D26: Aspect Ratio | E26: DeepNet/QPM narrow | F26: 51200 | G26: 1024 | H26: 1024 | I26: =1024*1024*64 -> 67108864 | J26: 16 | K26: =G26/J26 -> 64 | L26: =G26/J26 -> 64 | M26: =G26*4 -> 4096 | N26: =(1420000000000000/175000000000000)^0.74*N21 -> 1.4124285e+12 | O26: 1
A27: 24,576 | B27: 192 | C27: 128 | D27: 192 | E27: 1T | F27: 51200 | G27: =A27/4 -> 6144 | H27: 8192 | I27: =A27/D27 -> 128 | J27: =C27 -> 128 | K27: =G27/J27 -> 48 | L27: =G27/J27 -> 48 | M27: =G27*4 -> 24576 | N27: =300000000000000 -> 300000000000000 | O27: 1
A28: 32,768 | B28: 205 | C28: 160 | D28: 204.8 | E28: 2T | F28: 51200 | G28: =A28/4 -> 8192 | H28: 8192 | I28: =A28/D28 -> 160 | J28: =C28 -> 160 | K28: =G28/J28 -> 51.2 | L28: =G28/J28 -> 51.2 | M28: =G28*4 -> 32768 | N28: =300000000000000 -> 300000000000000 | O28: 1
A29: 40,960 | B29: 213 | C29: 192 | D29: 213.3 | E29: 4T | F29: 51200 | G29: =A29/4 -> 10240 | H29: 8192 | I29: =_xlfn.FLOOR.MATH(A29/D29) -> 192 | J29: =C29 -> 192 | K29: =G29/J29 -> 53.333333 | L29: =G29/J29 -> 53.333333 | M29: =G29*4 -> 40960 | N29: =300000000000000 -> 300000000000000 | O29: 1
A30: 50,176 | B30: 224 | C30: 224 | D30: 224 | E30: 7T | F30: 51200 | G30: =A30/4 -> 12544 | H30: 8192 | I30: =_xlfn.FLOOR.MATH(A30/D30) -> 224 | J30: =C30 -> 224 | K30: =G30/J30 -> 56 | L30: =G30/J30 -> 56 | M30: =G30*4 -> 50176 | N30: =300000000000000 -> 300000000000000 | O30: 1
A31: 60,416 | B31: 236 | C31: 256 | D31: 236 | E31: 11T | F31: 51200 | G31: =A31/4 -> 15104 | H31: 8192 | I31: =_xlfn.FLOOR.MATH(A31/D31) -> 256 | J31: =C31 -> 256 | K31: =G31/J31 -> 59 | L31: =G31/J31 -> 59 | M31: =G31*4 -> 60416 | N31: =300000000000000 -> 300000000000000 | O31: 1
A32: 70,656 | B32: 245 | C32: 288 | D32: 245 | E32: 18T | F32: 51200 | G32: =A32/4 -> 17664 | H32: 8192 | I32: =_xlfn.FLOOR.MATH(A32/D32) -> 288 | J32: =C32 -> 288 | K32: =G32/J32 -> 61.333333 | L32: =G32/J32 -> 61.333333 | M32: =G32*4 -> 70656 | N32: =300000000000000 -> 300000000000000 | O32: 1
A33: 81,920 | B33: 256 | C33: 320 | D33: 256 | E33: 26T | F33: 51200 | G33: =A33/4 -> 20480 | H33: 8192 | I33: =_xlfn.FLOOR.MATH(A33/D33) -> 320 | J33: =C33 -> 320 | K33: =G33/J33 -> 64 | L33: =G33/J33 -> 64 | M33: =G33*4 -> 81920 | N33: =300000000000000 -> 300000000000000 | O33: 1
A34: 94,208 | B34: 268 | C34: 352 | D34: 267.6 | E34: 37T | F34: 51200 | G34: =A34/4 -> 23552 | H34: 8192 | I34: =_xlfn.FLOOR.MATH(A34/D34) -> 352 | J34: =C34 -> 352 | K34: =G34/J34 -> 66.909091 | L34: =G34/J34 -> 66.909091 | M34: =G34*4 -> 94208 | N34: =300000000000000 -> 300000000000000 | O34: 1
A35: 106,496 | B35: 277 | C35: 384 | D35: 277.3 | E35: 53T | F35: 51200 | G35: =A35/4 -> 26624 | H35: 8192 | I35: =_xlfn.FLOOR.MATH(A35/D35) -> 384 | J35: =C35 -> 384 | K35: =G35/J35 -> 69.333333 | L35: =G35/J35 -> 69.333333 | M35: =G35*4 -> 106496 | N35: =300000000000000 -> 300000000000000 | O35: 1
A36: 119,808 | B36: 288 | C36: 416 | D36: 288 | E36: 72T | F36: 51200 | G36: =A36/4 -> 29952 | H36: 8192 | I36: =_xlfn.FLOOR.MATH(A36/D36) -> 416 | J36: =C36 -> 416 | K36: =G36/J36 -> 72 | L36: =G36/J36 -> 72 | M36: =G36*4 -> 119808 | N36: =300000000000000 -> 300000000000000 | O36: 1
A37: 134,144 | B37: 299 | C37: 448 | D37: 299.4 | E37: 96T | F37: 51200 | G37: =A37/4 -> 33536 | H37: 8192 | I37: =_xlfn.FLOOR.MATH(A37/D37) -> 448 | J37: =C37 -> 448 | K37: =G37/J37 -> 74.857143 | L37: =G37/J37 -> 74.857143 | M37: =G37*4 -> 134144 | N37: =300000000000000 -> 300000000000000 | O37: 1
A38: 148,480 | B38: 309 | C38: 480 | D38: 309.3 | E38: 128T | F38: 51200 | G38: =A38/4 -> 37120 | H38: 8192 | I38: =_xlfn.FLOOR.MATH(A38/D38) -> 480 | J38: =C38 -> 480 | K38: =G38/J38 -> 77.333333 | L38: =G38/J38 -> 77.333333 | M38: =G38*4 -> 148480 | N38: =300000000000000 -> 300000000000000 | O38: 1
E39: MoE-350M-128 | F39: 51200 | G39: 1024 | H39: 2048 | I39: 24 | J39: 16 | K39: 64 | L39: 64 | M39: =G39*4 -> 4096 | N39: =300000000000 -> 300000000000 | O39: 128
E40: MoE-1.3B-128 | F40: 51200 | G40: 2048 | H40: 2048 | I40: 24 | J40: 16 | K40: 128 | L40: 128 | M40: 8192 | N40: 300000000000 | O40: 128
E41: MoE-8B-64 | F41: 256000 | G41: 4096 | H41: 1024 | I41: 32 | J41: 32 | K41: 224 | L41: 224 | M41: 16384 | N41: 280000000000 | O41: 64
E42: MoE-64B-64 | F42: 256000 | G42: 8192 | H42: 1024 | I42: 64 | J42: 128 | K42: 112 | L42: 112 | M42: 32768 | N42: 280000000000000 | O42: 64
...

Sheet Performance Model
A1: Training time breakdown
A2: Parameter | B2: Total time to train (s) | C2: Total time to train (days) | D2: Total time to train (years) | E2: Computation time forward pass (s) | F2: Computation time backward pass (s) | G2: Computation time weight updates (s) | H2: Total computation time (s) | I2: Communication time forward pass: tensor parallellism intra node (s) | J2: Communication time forward pass: tensor parallellism inter node (s) | K2: Communication time forward pass: pipeline parallellism (s) | L2: Communication time forward pass: Zero-DP (ad-hoc model gathering) (s) | M2: Total communication time forward pass (s) | N2: Communication time backward pass: tensor parallellism intra node (s) | O2: Communication time backward pass: tensor parallellism inter node (s) | P2: Communication time backward pass: pipeline parallellism (s) | Q2: Communication time backward pass: Zero-DP (ad-hoc model gathering) (s) | R2: Total communication time backward pass (s) | S2: Communication time: all-reduce gradients for DP intra node (s) | T2: Communication time: all-reduce gradients for DP inter node (s) | U2: Communication time: all-reduce gradients for DP total (s) | V2: Total communication time (s) | W2: Waiting Time due to pipeline bubbles (s) | X2: total MACs | Y2: TFLOPS | Z2: total TFLOPS/sec | AA2: TFLOP/sec/GPU | AB2: TFLOP/sec/GPU (peak) | AC2: MoE FW pass communication overhead time (s) | AD2: MoE BW pass communication overhead time (s) | AE2: MoE Gating netowrk: compute overhead time (s) | AF2: Total MoE communication overhead time
A3: use calculation or override with user input | B3: calculated | C3: calculated | D3: calculated | E3: calculated | F3: calculated | G3: calculated | H3: calculated | I3: calculated | J3: calculated | K3: calculated | L3: calculated | M3: calculated | N3: calculated | O3: calculated | P3: calculated | Q3: calculated | R3: calculated | S3: calculated | T3: calculated | U3: calculated | V3: calculated | W3: calculated | X3: calculated | Y3: calculated | Z3: calculated | AA3: calculated | AB3: calculated | AC3: calculated | AD3: calculated | AE3: calculated | AF3: calculated
A4: Value used in formula | B4: =IF(B3=Inputs!$C$1,B5,B6) -> 3.5781399e+13 | C4: =IF(C3=Inputs!$C$1,C5,C6) -> 4.1413657e+08 | D4: =IF(D3=Inputs!$C$1,D5,D6) -> 1134620.7 | E4: =IF(E3=Inputs!$C$1,E5,E6) -> 1.0225248e+13 | F4: =IF(F3=Inputs!$C$1,F5,F6) -> 2.044585e+13 | G4: =IF(G3=Inputs!$C$1,G5,G6) -> 5.1103011e+12 | H4: =IF(H3=Inputs!$C$1,H5,H6) -> 3.5781399e+13 | I4: =IF(I3=Inputs!$C$1,I5,I6) -> 0 | ... AF4: =IF(AF3=Inputs!$C$1,AF5,AF6) -> 0
A5: user input value
A6: Calculated from more detail or defined earlier | B6: =B9 -> 3.5781399e+13 | C6: =B4/60/60/24 -> 4.1413657e+08 | D6: =C4/365 -> 1134620.7 | E6: =D23*C23*B23/(Inputs!J14*Inputs!K14*Inputs!L14) -> 1.0225248e+13 | F6: =F23*C23*B23/(Inputs!J14*Inputs!K14*Inputs!L14) -> 2.044585e+13 | G6: =B23*H23*C23/(Inputs!J14*Inputs!K14*Inputs!L14) -> 5.1103011e+12 | H6: =SUM(E4:G4) -> 3.5781399e+13 | I6: =B98*C23*B23 -> 0 | J6: =B108*C23*B23 -> 0 | K6: =MAX(D85,E85)*C23*B23 -> 0 | L6: =F85*(B85+C85+MAX(D85,E85))*C23*B23 -> 0 | M6: =SUM(I4:L4)+AC4 -> 0 | N6: =B161*C23*B23 -> 0 | O6: =B171*C23*B23 -> 0 | P6: =MAX(B181,B191)*C23*B23 -> 0 | Q6: =F154*(B161+B171+MAX(B181,B191))*C23*B23 -> 0 | R6: =SUM(N4:Q4)+AD4 -> 0 | S6: =B234*C23*B23 -> 0 | T6: =B244*B23*C23 -> 0 | U6: =S4+T4 -> 0 | V6: =M4+R4+U4+W6 -> 0 | W6: =B28*B23*C23 -> 0 | X6: =(C41+D41+F41+G41+C143+D143+E143+F143+C207)*C23*B23+M41*C23*B23/2 -> 7.4057799e+27 | Y6: =X6/10^12*2 -> 1.481156e+16 | Z6: =Y6/B19 -> 413.94579 | AA6: =Z6/Inputs!M14 -> 413.94579 | AB6: =Inputs!H28*8/Inputs!B7/1000000000000 -> 1857.9456 | AC6: =B23*C23*B268 -> 0 | AD6: =B23*C23*B277 -> 0 | AE6: =C23*B41*(M41/2)*_xlfn.CEILING.MATH(MAX(G53:H53)/I53) -> 0 | AF6: =AC4+AD4 -> 0
A7: comments
A8: Top Level
A9: Total Time to train (s) | B9: =MAX(B13,C13)+D13 -> 3.5781399e+13
A10: Assumptions | B10: assume it's known how instructions, operations, ... are split across accelerators and cpu cores up front (either by algorithm implementation, or by nature of said instructions and operations (seq, parallel, memory pattern , ...)
A11: Parameter | B11: Time estimated for all accelerator instructions (s) [T_multi_accel] | C11: Time estimated for all CPU instructions (s) [T_multi_cpu] | D11: Extra time lost because of dependencies between CPUs and accelerators (s) [D_cpu2accel]
A12: use calculation or override with user input | B12: calculated | C12: user input | D12: user input
A13: Value used in formula | B13: =IF(B12=Inputs!$C$1,B14,B15) -> 3.5781399e+13 | C13: =IF(C12=Inputs!$C$1,C14,C15) -> 0 | D13: =IF(D12=Inputs!$C$1,D14,D15) -> 0
A14: user input value | C14: 0 | D14: 0
A15: Calculated from more detail | B15: =B19 -> 3.5781399e+13 | C15: insert cpu model | D15: insert dependency model
A16: comments | C16: cpu model is not needed as we assume time is dominated by accelerator
A18: Time spent in Multi GPU (s)
A19: C_multi_accel (s) | B19: =B23*C23*((D23+F23+H23)/(Inputs!J14*Inputs!K14*Inputs!L14)+E23+J23+G23+K23) -> 3.5781399e+13
A20: Assumptions | B20: layers are assumed uniform based on the average layer size and average connectivity between neurons (easy to extend in the formula, but not in excel)
A21: Parameter | B21: number of batches [N_batch] | C21: number of layers [L] | D21: Compute time forward pass (s) [U_f] | E21: Communication time forward pass (s) [M_f] | F21: Compute time backward pass (s) [U_b] | G21: Communication time backward pass (s) [M_b] | H21: Weight update time (s) [U_w] | I21: data parallellism degree [N_DP] (how many copies of the model) | J21: Communication time spent in allreduce (s) [M_all] | K21: Waiting time due to pipeline bubbles (s) [T_wait] | L21: Microbatches (N_microbatch) | M21: Degree of pipeline parallelism (N_PP) | N21: Degree of tensor parallelism (N_TP)
A22: use calculation or override with user input | B22: calculated | C22: calculated | D22: calculated | E22: calculated | F22: calculated | G22: calculated | H22: calculated | I22: calculated | J22: calculated | K22: calculated | L22: calculated | M22: calculated | N22: calculated
A23: Value used in formula | B23: =IF(B22=Inputs!$C$1,B24,B25) -> 7152557.4 | C23: =IF(C22=Inputs!$C$1,C24,C25) -> 480 | D23: =IF(D22=Inputs!$C$1,D24,D25) -> 2978.3193 | E23: =IF(E22=Inputs!$C$1,E24,E25) -> 0 | F23: =IF(F22=Inputs!$C$1,F24,F25) -> 5955.2855 | G23: =IF(G22=Inputs!$C$1,G24,G25) -> 0 | H23: =IF(H22=Inputs!$C$1,H24,H25) -> 1488.4831 | I23: =IF(I22=Inputs!$C$1,I24,I25) -> 1 | ... N23: =IF(N22=Inputs!$C$1,N24,N25) -> 1
A24: user input value | J24: 0
A25: Calculated from more detail or defined earlier | B25: =Inputs!M7 -> 7152557.4 | C25: =Inputs!N7 -> 480 | D25: =B37 -> 2978.3193 | E25: =B81 -> 0 | F25: =B139 -> 5955.2855 | G25: =B150 -> 0 | H25: =B203 -> 1488.4831 | I25: =Inputs!J14 -> 1 | J25: =B226 -> 0 | K25: =B28 -> 0 | L25: =Inputs!B14 -> 1 | M25: =Inputs!L14 -> 1 | N25: =Inputs!K14 -> 1
A26: comments
A27: Waiting time due to pipeline bubbles per batch (s)
A28: T_wait (s) | B28: =B32*(Inputs!L14-1)*((D23+F23)/(Inputs!J14*Inputs!K14*Inputs!L14*Inputs!N7)+E23+G23)/Inputs!B14 -> 0
A29: Assumptions | B29: assuming naive pipeline, but you can scale it down with the non overlapping factor
A30: Parameter | B30: non_overlapping pipeline bubbles [R_non_overlapping]
A31: use calculation or override with user input | B31: user input
A32: Value used in formula | B32: =IF(B31=Inputs!$C$1,B33,B34) -> 1
A33: user input value | B33: 1
A34: Calculated from more detail or defined earlier
A35: comments
A36: Compute time forward pass (s) (full batch, as we scale with parallellism steps above already to model minibatch/microbatch)
A37: U_f (s) | B37: =B41*(C41+D41+M41/2+N41)*_xlfn.CEILING.MATH(MAX(G53:H53)/I53)+E41*(F41+G41)*_xlfn.CEILING.MATH(Inputs!C7/G73) -> 2978.3193
A38: Assumptions
A39: Parameter | B39: reciprocal of throughput of MAC ops (s/OP) [C_MAC] | C39: Number of MACs performed in layer l, sublayer i [N_MAC(l,i)] for attention sublayer | D39: Number of MACs performed in layer l, sublayer i [N_MAC(l,i)] for fullyconnected sublayer | E39: reciprocal of throughput of nonlinear function calculation (s/ACT) [C_nonlin] | F39: Number of nonlinear operations in layer l, sublayer i (N_nonlin(l,i)) for attention sublayer | G39: Number of nonlinear operations in layer l, sublayer i (N_nonlin(l,i)) for fullyconnected sublayer | H39: Precision of weights in layer l, sublayer i (S_param (l,i)) for attention sublayer | I39: Precision of weights in layer l, sublayer i (S_param (l,i)) for fullyconnected sublayer | J39: MAC_bitwidth (W_FU_MAC) | K39: Precision of activations in layer l, sublayer i (S_activation(l,i)) for attention sublayer | L39: Precision of activations in layer l, sublayer i (S_activation(l,i)) for fully connected sublayer | M39: Number of Gating MACs per layer | N39: Decoder MACs
A40: use calculation or override with user input | B40: calculated | C40: calculated | D40: calculated | E40: calculated | F40: calculated | G40: calculated | H40: calculated | I40: calculated | J40: user input | K40: calculated | L40: calculated | M40: calculated | N40: calculated
A41: Value used in formula | B41: =IF(B40=Inputs!$C$1,B42,B43) -> 2.0701111e-15 | C41: =IF(C40=Inputs!$C$1,C42,C43) -> 2.5668099e+17 | D41: =IF(D40=Inputs!$C$1,D42,D43) -> 4.6234464e+17 | E41: =IF(E40=Inputs!$C$1,E42,E43) -> 4.3402778e-13 | F41: =IF(F40=Inputs!$C$1,F42,F43) -> 1.5569256e+12 | G41: =IF(G40=Inputs!$C$1,G42,G43) -> 1900544000 | H41: =IF(H40=Inputs!$C$1,H42,H43) -> 16 | I41: =IF(I40=Inputs!$C$1,I42,I43) -> 16 | ... N41: =IF(N40=Inputs!$C$1,N42,N43) -> 9730785280000
...

Sheet Data to be transfered
A1: Intra | C1: Inter
A2: TP | C2: TP
A3: Forward pass (Bits) | B3: Backward pass (Bits) | C3: Forward pass (Bits) | D3: Backward pass (Bits)
A4: ='Performance Model'!F102*Inputs!D14+'Performance Model'!C102*'Performance Model'!D102*'Performance Model'!F102 -> 0 | C4: ='Performance Model'!F112*Inputs!H14+'Performance Model'!C112*'Performance Model'!D112*'Performance Model'!F112 -> 0

Sheet Scenario Summary
B2: Breakdown | C2: ='Performance Model'!B2 -> Total time to train (s) | D2: ='Performance Model'!C2 -> Total time to train (days) | E2: ='Performance Model'!D2 -> Total time to train (years) | F2: ='Performance Model'!E2 -> Computation time forward pass (s) | G2: ='Performance Model'!F2 -> Computation time backward pass (s) | H2: ='Performance Model'!G2 -> Computation time weight updates (s) | I2: ='Performance Model'!H2 -> Total computation time (s) | J2: ='Performance Model'!I2 -> Communication time forward pass: tensor parallellism intra node (s) | ... V2: ='Performance Model'!U2 -> Communication time: all-reduce gradients for DP total (s) | W2: Total MoE communication overhead | X2: ='Performance Model'!V2 -> Total communication time (s) | Y2: ='Performance Model'!W2 -> Waiting Time due to pipeline bubbles (s) | Z2: ='Performance Model'!X2 -> total MACs | AA2: ='Performance Model'!Y2 -> TFLOPS | AB2: ='Performance Model'!Z2 -> total TFLOPS/sec | AC2: ='Performance Model'!AA2 -> TFLOP/sec/GPU | AD2: ='Performance Model'!AB2 -> TFLOP/sec/GPU (peak) | AE2: ='Energy Model'!C2 -> Total energy to train (J) | AF2: ='Energy Model'!D2 -> Average overall power (W) | AG2: ='Energy Model'!E2 -> Energy efficiency (ops/s/W or ops/J) ) aka inverse of power delay product | AH2: ='Energy Model'!F2 -> (ops/s)^2/W aka inverse of energy-delay product | AI2: ='Energy Model'!G2 -> (ops/s)^3/W aka inverse of energy-delay-square prodct | AJ2: ='Energy Model'!H2 -> Energy due to accelerators computing | AK2: ='Energy Model'!I2 -> Energy due to accelerators idling | AL2: ='Energy Model'!J2 -> Energy due to intra node communication | ... AO2: ='Energy Model'!M2 -> Energy due to overhead of datacenter
B3: Current configuration: | C3: ='Performance Model'!B4 -> 3.5781399e+13 | D3: ='Performance Model'!C4 -> 4.1413657e+08 | E3: ='Performance Model'!D4 -> 1134620.7 | F3: ='Performance Model'!E4 -> 1.0225248e+13 | G3: ='Performance Model'!F4 -> 2.044585e+13 | H3: ='Performance Model'!G4 -> 5.1103011e+12 | I3: ='Performance Model'!H4 -> 3.5781399e+13 | J3: ='Performance Model'!I4 -> 0 | ... V3: ='Performance Model'!U4 -> 0 | W3: ='Performance Model'!AF4 -> 0 | X3: ='Performance Model'!V4 -> 0 | Y3: ='Performance Model'!W4 -> 0 | Z3: ='Performance Model'!X4 -> 7.4057799e+27 | AA3: ='Performance Model'!Y4 -> 1.481156e+16 | AB3: ='Performance Model'!Z4 -> 413.94579 | AC3: ='Performance Model'!AA4 -> 413.94579 | AD3: ='Performance Model'!AB4 -> 1857.9456 | AE3: ='Energy Model'!C4 -> 8.3299098e+16 | AF3: ='Energy Model'!D4 -> 2328 | AG3: ='Energy Model'!E4 -> 1.7781177e+11 | AH3: ='Energy Model'!F4 -> 7.3604433e+25 | AI3: ='Energy Model'!G4 -> 3.0468245e+40 | AJ3: ='Energy Model'!H4 -> 2.2900096e+16 | AK3: ='Energy Model'!I4 -> 0 | AL3: ='Energy Model'!J4 -> 0 | ... AO3: ='Energy Model'!M4 -> 1.3883183e+16
B4: relative: | F4: =F3/$C$3 -> 0.28576993 | G4: =G3/$C$3 -> 0.57141002 | H4: =H3/$C$3 -> 0.14282005 | I4: =I3/$C$3 -> 1 | J4: =J3/$C$3 -> 0 | K4: =K3/$C$3 -> 0 | L4: =L3/$C$3 -> 0 | M4: =M3/$C$3 -> 0 | ... Y4: =Y3/$C$3 -> 0 | AJ4: =AJ3/$AE$3 -> 0.27491409 | AK4: =AK3/$AE$3 -> 0 | AL4: =AL3/$AE$3 -> 0 | AM4: =AM3/$AE$3 -> 0 | AN4: =AN3/$AE$3 -> 0.55841924 | AO4: =AO3/$AE$3 -> 0.16666667
B6: Copy values over in below table to create multiple data points to plot
B7: Configuration | C7: ='Performance Model'!B2 -> Total time to train (s) | D7: ='Performance Model'!C2 -> Total time to train (days) | E7: ='Performance Model'!D2 -> Total time to train (years) | F7: ='Performance Model'!E2 -> Computation time forward pass (s) | G7: ='Performance Model'!F2 -> Computation time backward pass (s) | H7: ='Performance Model'!G2 -> Computation time weight updates (s) | I7: ='Performance Model'!H2 -> Total computation time (s) | J7: ='Performance Model'!I2 -> Communication time forward pass: tensor parallellism intra node (s) | ... V7: ='Performance Model'!U2 -> Communication time: all-reduce gradients for DP total (s) | W7: Total MoE communication overhead | X7: ='Performance Model'!V2 -> Total communication time (s) | Y7: ='Performance Model'!W2 -> Waiting Time due to pipeline bubbles (s) | Z7: ='Performance Model'!X2 -> total MACs | AA7: ='Performance Model'!Y2 -> TFLOPS | AB7: ='Performance Model'!Z2 -> total TFLOPS/sec | AC7: ='Performance Model'!AA2 -> TFLOP/sec/GPU | AD7: ='Performance Model'!AB2 -> TFLOP/sec/GPU (peak) | AE7: ='Energy Model'!C2 -> Total energy to train (J) | AF7: ='Energy Model'!D2 -> Average overall power (W) | AG7: ='Energy Model'!E2 -> Energy efficiency (ops/s/W or ops/J) ) aka inverse of power delay product | AH7: ='Energy Model'!F2 -> (ops/s)^2/W aka inverse of energy-delay product | AI7: ='Energy Model'!G2 -> (ops/s)^3/W aka inverse of energy-delay-square prodct | AJ7: ='Energy Model'!H2 -> Energy due to accelerators computing | AK7: ='Energy Model'!I2 -> Energy due to accelerators idling | AL7: ='Energy Model'!J2 -> Energy due to intra node communication | ... AO7: ='Energy Model'!M2 -> Energy due to overhead of datacenter
B8: Test config 1 | C8: 1175164 | D8: 13.601435 | E8: 0.037264205 | F8: 130803.83 | G8: 261274.84 | H8: 65785.95 | I8: 457864.62 | J8: 50177.282 | K8: 0 | L8: 2688.0143 | M8: 13216.324 | N8: 108328.3 | O8: 100353.28 | P8: 0 | Q8: 5376.0143 | R8: 26432.324 | S8: 216597.3 | T8: 0 | U8: 88364.989 | V8: 88364.989 | W8: 126682.36 | X8: 413290.59 | Y8: 113985.24 | Z8: 5.7257777e+22 | AA8: 1.1451555e+11 | AB8: 97446.447 | AC8: 63.441698 | AD8: 311.86944 | AE8: 7.2089147e+11 | AF8: 613439.05 | AG8: 1.588527e+11 | AH8: 1.5479631e+28 | AI8: 1.508435e+45 | AJ8: 2.3911522e+11 | AK8: 5.6692696e+10 | AL8: 8.8801284e+09 | AM8: 2733922560 | AN8: 2.9332093e+11 | AO8: 1.2014858e+11
B9: Test config 2 | C9: 786549.42 | D9: 9.1035813 | E9: 0.024941319 | F9: 41966.453 | G9: 83776.482 | H9: 21081.407 | I9: 146824.34 | J9: 33451.948 | K9: 0 | L9: 2688.0143 | M9: 9034.9907 | N9: 87397.132 | O9: 66902.615 | P9: 0 | Q9: 5376.0143 | R9: 18069.657 | S9: 174734.96 | T9: 0 | U9: 88364.989 | V9: 88364.989 | W9: 126608.86 | X9: 350497.09 | Y9: 99314.713 | Z9: 5.7257777e+22 | AA9: 1.1451555e+11 | AB9: 145592.32 | AC9: 94.786666 | AD9: 973.2096 | AE9: 3.8604238e+11 | AF9: 490804.99 | AG9: 2.9663985e+11 | AH9: 4.3188484e+28 | AI9: 6.2879115e+45 | AJ9: 6.5401435e+10 | AK9: 4.8363765e+10 | AL9: 8.8801284e+09 | AM9: 2733922560 | AN9: 1.9632274e+11 | AO9: 6.4340397e+10
B10: Test config 3 | C10: 2836739.9 | D10: 32.832638 | E10: 0.089952432 | F10: 438548.01 | G10: 876895.05 | H10: 379601.24 | I10: 1695044.3 | J10: 57344.961 | K10: 0 | L10: 3072.0072 | M10: 15104.242 | N10: 160787.49 | O10: 114688.96 | P10: 0 | Q10: 6144.0072 | R10: 30208.242 | S10: 309732.56 | T10: 0 | U10: 119266.82 | V10: 119266.82 | W10: 243957.63 | X10: 589786.87 | Y10: 185972.29 | Z10: 6.0030009e+23 | AA10: 1.2006002e+12 | AB10: 423232.38 | AC10: 275.54191 | AD10: 973.2096 | AE10: 1.8784921e+12 | AF10: 662201.02 | AG10: 6.3912975e+11 | AH10: 2.705004e+29 | AI10: 1.1448453e+47 | AJ10: 7.5504053e+11 | AK10: 8.3409625e+10 | AL10: 1.5223121e+10 | AM10: 3686499360 | AN10: 7.0805028e+11 | AO10: 3.1308201e+11
W14: For 32 Nodes
W16: Infini-Infini
W17: NV-Infini
W18: NV-NV | X18: 217745.97 | Y18: =X18/3600 -> 60.484992
W19: Optical-NV | Y19: =X19/3600 -> 0
W20: NV-Optical | Y20: =X20/3600 -> 0
W21: Optical-Optical | X21: 3937.0938 | Y21: =X21/3600 -> 1.0936372

Sheet Communication specs
A1: Tech | B1: Bandwidth bps
A2: Infiniband HDR 4 links | B2: 200000000000
A3: Infiniband HDR 8 links | B3: 400000000000
A4: PCIe4_x4 | B4: =7899000000*8 -> 63192000000
A5: PCIe4_x8 | B5: =15754000000*8 -> 126032000000
A6: PCIe4_x16 | B6: =31508000000*8 -> 252064000000
A7: PCIe5_x4 | B7: =15754000000*8 -> 126032000000
A8: PCIe5_x8 | B8: =31508000000*8 -> 252064000000
A9: PCIe5_x16 | B9: =63015000000*8 -> 504120000000
A10: NVLink_Gen2 | B10: =300000000000*8/2 -> 1200000000000
A11: NVLink_Gen3 | B11: =600000000000*8/2 -> 2400000000000
A12: NVLink_Gen4 | B12: =900000000000*8/2 -> 3600000000000
A13: RoCE | B13: 800000000000
A14: Optical OIO 25Tx1 | B14: 25000000000000
A15: Optical OIO 25Tx2 | B15: =2*25000000000000 -> 50000000000000
A16: Optical OIO 25Tx4 | B16: =4*25000000000000 -> 100000000000000
A17: Optical OIO 25Tx8 | B17: =8*25000000000000 -> 200000000000000
A18: Optical OIO 25Tx16 | B18: =16*25000000000000 -> 400000000000000
A19: Optical OIO 25Tx32 | B19: =32*25000000000000 -> 800000000000000
A20: Optical OIO Taper-5 | B20: =B17/5 -> 40000000000000

Sheet HBM3+2d SRAM
A3: Time spent (data traffic)
A4: T_mem (in sec) | B4: =MAX(H30/L21,J48/G21) -> 0.0015625
A8: Application/Mapping specific parameters
A9: Assumptions
A10: Parameter | B10: Linear dimension of the compute block (N_x) | C10: # of computation points that we wish to parallelize | D10: #threads required as per the application | E10: # thread blocks | F10: # groups
A11: use calculation or override with user input | B11: user input | C11: calculated | D11: calculated | E11: calculated | F11: calculated
A12: Value used in formula | B12: =IF(B11=Inputs!$C$1,B13,B14) -> 256 | C12: =IF(C11=Inputs!$C$1,C13,C14) -> 16777216 | D12: =IF(D11=Inputs!$C$1,D13,D14) -> 16777216 | E12: =IF(E11=Inputs!$C$1,E13,E14) -> 131072 | F12: =IF(F11=Inputs!$C$1,F13,F14) -> 102.4
A13: user input value | B13: 256
A14: Calculated from more detail or defined earlier | B14: =B27 -> 0 | C14: =B12*B12*B12 -> 16777216 | D14: =C12 -> 16777216 | E14: =D12/D21 -> 131072 | F14: =E12/K21 -> 102.4
A15: comments
A17: Hardware specs
A18: Assumptions
A19: Parameter | B19: Number of threads per SM | C19: Number of SMs | D19: # threads per block | E19: Clock rate (R) in GHz | F19: BW per SM (GB/s) | G19: BW_GM (GB/s) | H19: on-SM storage (KB) | I19: occupancy | J19: # thread blocks per SM | K19: # thread blocks per group | L19: Total BW_SM (GB/s) | M19: SM-cache-line-size (B)
A20: use calculation or override with user input | B20: user input | C20: user input | D20: user input | E20: user input | F20: user input | G20: user input | H20: user input | I20: user input | J20: calculated | K20: calculated | L20: calculated | M20: user input
A21: Value used in formula | B21: =IF(B20=Inputs!$C$1,B22,B23) -> 2048 | C21: =IF(C20=Inputs!$C$1,C22,C23) -> 80 | D21: =IF(D20=Inputs!$C$1,D22,D23) -> 128 | E21: =IF(E20=Inputs!$C$1,E22,E23) -> 0.71 | F21: =IF(F20=Inputs!$C$1,F22,F23) -> 10 | G21: =IF(G20=Inputs!$C$1,G22,G23) -> 6451 | H21: =IF(H20=Inputs!$C$1,H22,H23) -> 256 | I21: 1 | J21: =IF(J20=Inputs!$C$1,J22,J23) -> 16 | K21: =IF(K20=Inputs!$C$1,K22,K23) -> 1280 | L21: =IF(L20=Inputs!$C$1,L22,L23) -> 800 | M21: =IF(M20=Inputs!$C$1,M22,M23) -> 128
A22: user input value | B22: 2048 | C22: 80 | D22: 128 | E22: 0.71 | F22: 10 | G22: 6451 | H22: 256 | L22: 0 | M22: 128
A23: Calculated from more detail or defined earlier | B23: 0 | C23: 0 | D23: 0 | E23: 0 | F23: 0 | G23: 0 | H23: 0 | I23: 1 | J23: =B21/D21 -> 16 | K23: =J21*C21 -> 1280 | L23: =F21*C21 -> 800 | M23: 0
A24: comments
A26: On SM to thread private registers
A27: Assumptions
A28: Parameter | B28: Precesion (byte) | C28: Number of threads per SM | D28: number of loads per thread from the on-SM storage to registers | E28: number of corresponding stores per thread | F28: no of algined (with L1 cache-line of 128B) loads | G28: no of miss-algined loads | H28: traffic volume between SM and registers (V_SM) in GB | I28: time
A29: use calculation or override with user input | B29: user input | C29: calculated | D29: calculated | E29: user input | F29: user input | G29: user input | H29: calculated | I29: calculated
A30: Value used in formula | B30: =IF(B29=Inputs!$C$1,B31,B32) -> 8 | C30: =IF(C29=Inputs!$C$1,C31,C32) -> 2048 | D30: =IF(D29=Inputs!$C$1,D31,D32) -> 9 | E30: =IF(E29=Inputs!$C$1,E31,E32) -> 1 | F30: =IF(F29=Inputs!$C$1,F31,F32) -> 5 | G30: =IF(G29=Inputs!$C$1,G31,G32) -> 2 | H30: =IF(H29=Inputs!$C$1,H31,H32) -> 1.25 | I30: =IF(I29=Inputs!$C$1,I31,I32) -> 0.0015625
A31: user input value | B31: 8 | D31: 20 | E31: 1 | F31: 5 | G31: 2
A32: Calculated from more detail or defined earlier | B32: 0 | C32: =B21 -> 2048 | D32: =F30+2*G30 -> 9 | E32: 0 | F32: 0 | G32: 0 | H32: =C12*B30*(D30+E30)/1024^3 -> 1.25 | I32: =H30/L21 -> 0.0015625
A33: comments
D34: =B4 -> 0.0015625
A36: Assumption | B36: assuming that the CUDA thread blocks are scheduled to the SMXs in a cyclic order; thus, the thread blocks designated to the same SMX do not share data in the on-SMX storage
A37: Parameter | B37: Number of threads blocks | C37: number of data values stored per thread block
A38: use calculation or override with user input | B38: calculated | C38: calculated
A39: Value used in formula | B39: =IF(B38=Inputs!$C$1,B40,B41) -> 131072 | C39: =IF(C38=Inputs!$C$1,C40,C41) -> 128
A40: user input value
A41: Calculated from more detail or defined earlier | B41: =E12 -> 131072 | C41: =E30*D21 -> 128
A42: comments | B42: delta is a HW specific fitting parameter that connects the capacity miss ratio with the total data volume needed by the active thread blocks in the same SMX
A44: Global memory (GM) to SM
A45: Assumption | B45: the basic granularity here is an entire group of simultaneously active thread blocks. L2 cache is shared across all active thread blocks. We assume that the whole computation is divided into several such groups. Since
A46: Parameter | B46: Precesion | C46: Number of threads block groups | D46: number of data values loads per group from global memory to SM | E46: number of data values stored per group | F46: no of mandatory values loaded per group | G46: SM miss ratio | H46: epsilon | I46: # thread blocks per group | J46: traffic volume between GM and SM (V_GM) in GB | K46: width_y | L46: height_z | M46: test_time | N46: reuse | O46: traffic ration: SM/GM
A47: use calculation or override with user input | B47: calculated | C47: calculated | D47: calculated | E47: calculated | F47: calculated | G47: calculated | H47: user input | I47: calculated | J47: calculated | K47: user input | L47: user input | M47: calculated | N47: calculated | O47: calculated
A48: Value used in formula | B48: =IF(B47=Inputs!$C$1,B49,B50) -> 8 | C48: =IF(C47=Inputs!$C$1,C49,C50) -> 102.4 | D48: =IF(D47=Inputs!$C$1,D49,D50) -> 94143.701 | E48: =IF(E47=Inputs!$C$1,E49,E50) -> 163840 | F48: =IF(F47=Inputs!$C$1,F49,F50) -> 91584 | G48: =IF(G47=Inputs!$C$1,G49,G50) -> 0.027949219 | H48: =IF(H47=Inputs!$C$1,H49,H50) -> 0.01 | I48: =IF(I47=Inputs!$C$1,I49,I50) -> 1280 | ... O48: =IF(O47=Inputs!$C$1,O49,O50) -> 508.0631
A49: user input value | F49: 20480000 | G49: 2000 | H49: 0.01 | K49: 106 | L49: 3
...

Sheet LPDDR6+3d_SRAM
A3: Time spent (data traffic)
A4: T_mem (in sec) | B4: =MAX(H30/L21,J48/G21) -> 0.00024577963
A8: Application/Mapping specific parameters
A9: Assumptions
A10: Parameter | B10: Linear dimension of the compute block (N_x) | C10: # of computation points that we wish to parallelize | D10: #threads required as per the application | E10: # thread blocks | F10: # groups
A11: use calculation or override with user input | B11: user input | C11: calculated | D11: calculated | E11: calculated | F11: calculated
A12: Value used in formula | B12: =IF(B11=Inputs!$C$1,B13,B14) -> 256 | C12: =IF(C11=Inputs!$C$1,C13,C14) -> 16777216 | D12: =IF(D11=Inputs!$C$1,D13,D14) -> 16777216 | E12: =IF(E11=Inputs!$C$1,E13,E14) -> 131072 | F12: =IF(F11=Inputs!$C$1,F13,F14) -> 102.4
A13: user input value | B13: 256
A14: Calculated from more detail or defined earlier | B14: =B27 -> 0 | C14: =B12*B12*B12 -> 16777216 | D14: =C12 -> 16777216 | E14: =D12/D21 -> 131072 | F14: =E12/K21 -> 102.4
A15: comments
A17: Hardware specs
A18: Assumptions
A19: Parameter | B19: Number of threads per SM | C19: Number of SMs | D19: # threads per block | E19: Clock rate (R) in GHz | F19: BW per SM (GB/s) | G19: BW_GM (GB/s) | H19: read only data cache size per SM (KB) | I19: occupancy | J19: # thread blocks per SM | K19: # thread blocks per group | L19: Total BW_SM (GB/s) | M19: SM-cache-line-size (B)
A20: use calculation or override with user input | B20: user input | C20: user input | D20: user input | E20: user input | F20: user input | G20: user input | H20: user input | I20: user input | J20: calculated | K20: calculated | L20: calculated | M20: user input
A21: Value used in formula | B21: =IF(B20=Inputs!$C$1,B22,B23) -> 2048 | C21: =IF(C20=Inputs!$C$1,C22,C23) -> 80 | D21: =IF(D20=Inputs!$C$1,D22,D23) -> 128 | E21: =IF(E20=Inputs!$C$1,E22,E23) -> 0.71 | F21: =IF(F20=Inputs!$C$1,F22,F23) -> 191 | G21: =IF(G20=Inputs!$C$1,G22,G23) -> 1593.7 | H21: =IF(H20=Inputs!$C$1,H22,H23) -> 1024 | I21: 1 | J21: =IF(J20=Inputs!$C$1,J22,J23) -> 16 | K21: =IF(K20=Inputs!$C$1,K22,K23) -> 1280 | L21: =IF(L20=Inputs!$C$1,L22,L23) -> 15280 | M21: =IF(M20=Inputs!$C$1,M22,M23) -> 256
A22: user input value | B22: 2048 | C22: 80 | D22: 128 | E22: 0.71 | F22: 191 | G22: 1593.7 | H22: 1024 | L22: 0 | M22: 256
A23: Calculated from more detail or defined earlier | B23: 0 | C23: 0 | D23: 0 | E23: 0 | F23: 0 | G23: 0 | H23: 0 | I23: 1 | J23: =B21/D21 -> 16 | K23: =J21*C21 -> 1280 | L23: =F21*C21 -> 15280 | M23: 0
A24: comments
A26: On SM to thread private registers
A27: Assumptions
A28: Parameter | B28: Precesion (byte) | C28: Number of threads per SM | D28: number of loads per thread from the on-SM storage to registers | E28: number of corresponding stores per thread | F28: no of algined (with L1 cache-line of 128B) loads | G28: no of miss-algined loads | H28: traffic volume between SM and registers (V_SM) in GB | I28: time
A29: use calculation or override with user input | B29: user input | C29: calculated | D29: calculated | E29: user input | F29: user input | G29: user input | H29: calculated | I29: calculated
A30: Value used in formula | B30: =IF(B29=Inputs!$C$1,B31,B32) -> 16 | C30: =IF(C29=Inputs!$C$1,C31,C32) -> 2048 | D30: =IF(D29=Inputs!$C$1,D31,D32) -> 9 | E30: =IF(E29=Inputs!$C$1,E31,E32) -> 1 | F30: =IF(F29=Inputs!$C$1,F31,F32) -> 5 | G30: =IF(G29=Inputs!$C$1,G31,G32) -> 2 | H30: =IF(H29=Inputs!$C$1,H31,H32) -> 2.5 | I30: =IF(I29=Inputs!$C$1,I31,I32) -> 0.00016361257
A31: user input value | B31: 16 | D31: 20 | E31: 1 | F31: 5 | G31: 2
A32: Calculated from more detail or defined earlier | B32: 0 | C32: =B21 -> 2048 | D32: =F30+2*G30 -> 9 | E32: 0 | F32: 0 | G32: 0 | H32: =C12*B30*(D30+E30)/1024^3 -> 2.5 | I32: =H30/L21 -> 0.00016361257
A33: comments
D34: =B4 -> 0.00024577963
A36: Assumption | B36: assuming that the CUDA thread blocks are scheduled to the SMXs in a cyclic order; thus, the thread blocks designated to the same SMX do not share data in the on-SMX storage
A37: Parameter | B37: Number of threads blocks | C37: number of data values stored per thread block
A38: use calculation or override with user input | B38: calculated | C38: calculated
A39: Value used in formula | B39: =IF(B38=Inputs!$C$1,B40,B41) -> 131072 | C39: =IF(C38=Inputs!$C$1,C40,C41) -> 128
A40: user input value
A41: Calculated from more detail or defined earlier | B41: =E12 -> 131072 | C41: =E30*D21 -> 128
A42: comments | B42: delta is a HW specific fitting parameter that connects the capacity miss ratio with the total data volume needed by the active thread blocks in the same SMX
A44: Global memory (GM) to SM
A45: Assumption | B45: the basic granularity here is an entire group of simultaneously active thread blocks. L2 cache is shared across all active thread blocks. We assume that the whole computation is divided into several such groups. Since
A46: Parameter | B46: Precesion | C46: Number of threads block groups | D46: number of data values loads per group from global memory to L2 cache | E46: number of data values stored per group | F46: no of mandatory values loaded per group | G46: SM miss ratio | H46: epsilon | I46: # thread blocks per group | J46: traffic volume between GM and L2 (V_GM) in GB | K46: width_y | L46: height_z | M46: test_time
A47: use calculation or override with user input | B47: calculated | C47: calculated | D47: calculated | E47: calculated | F47: calculated | G47: calculated | H47: user input | I47: calculated | J47: calculated | K47: user input | L47: user input | M47: calculated
A48: Value used in formula | B48: =IF(B47=Inputs!$C$1,B49,B50) -> 16 | C48: =IF(C47=Inputs!$C$1,C49,C50) -> 102.4 | D48: =IF(D47=Inputs!$C$1,D49,D50) -> 92863.851 | E48: =IF(E47=Inputs!$C$1,E49,E50) -> 163840 | F48: =IF(F47=Inputs!$C$1,F49,F50) -> 91584 | G48: =IF(G47=Inputs!$C$1,G49,G50) -> 0.013974609 | H48: =IF(H47=Inputs!$C$1,H49,H50) -> 0.01 | I48: =IF(I47=Inputs!$C$1,I49,I50) -> 1280 | ... M48: =IF(M47=Inputs!$C$1,M49,M50) -> 0.00024577963
A49: user input value | F49: 1000000 | G49: 2000 | H49: 0.01 | K49: 106 | L49: 3
...

Sheet Validation
A2: Megatron 18.4B | B2: 135
A3: Megatron 7.5B | B3: 142
A4: Megatron 145B | B4: 148
A9: Validation_results
A10: Model size | B10: modeled | C10: paper
A11: model 7.2B | B11: 169.35 | C11: 142
A12: model 145B | B12: 147 | C12: 148
A13: model 310B | B13: 162 | C13: 155
A14: model 530B | B14: 148.6 | C14: 163
A15: model 1T | B15: 144.3 | C15: 163
A18: batchsize | B18: modeled | C18: paper
A19: 12 | B19: 106.7 | C19: 121
A20: 24 | B20: 123 | C20: 130
A21: 36 | B21: 134 | C21: 137
A22: 48 | B22: 142 | C22: 142
A23: 60 | B23: 148 | C23: 145
A28: GPT(3), 2.2-2.5 B | B28: modeled | C28: Paper (MS, PipeDream'21) | D28: Comments
A29: Performance (seq/s/GPU) | B29: 108 | C29: 80 | D29: 32 ubatchs, B=2048, 8x8 V100
B31: TFLOP/S/GPU
A32: Megatron 145B - A100 | B32: 115.35
A33: Megatron 145B - V100 | B33: 43.14
F42: Model size | G42: modeled | H42: paper
F43: model 145B | G43: 147 | H43: 148
F44: model 310B | G44: 162 | H44: 155
F45: model 530B | G45: 148.6 | H45: 163
F46: model 1T | G46: 144.3 | H46: 163
A55: Megatron 5.9B-tp-dp-batch128 | B55: modeled | C55: paper
A56: tp2-dp32 | B56: 130.56 | C56: 102
A57: tp4-dp16 | B57: 161.4 | C57: 95
A61: =Inputs!G14 -> 1 | B61: =Inputs!C14 -> 1 | C61: =Inputs!H14 -> 1 | D61: =Inputs!D14 -> 1 | E61: =Inputs!I14 -> 1 | F61: =Inputs!E14 -> 1 | G61: ='Performance Model'!C4 -> 4.1413657e+08 | H61: =Inputs!M14 -> 1
A62: DP_inter | B62: DP_intra | C62: TP_iner | D62: TP_intra | E62: PP_inter | F62: PP_intra | G62: T_exec | H62: #tot_acc | I62: DP | J62: TP | K62: PP | L62: T_exec
A63: 128 | B63: 8 | C63: 1 | D63: 1 | E63: 1 | F63: 1 | G63: 38.015256 | H63: 1024 | I63: =A63*B63 -> 1024 | J63: =C63*D63 -> 1 | K63: =E63*F63 -> 1 | L63: =G63 -> 38.015256
A64: 128 | B64: 1 | C64: 1 | D64: 8 | E64: 1 | F64: 1 | G64: 17.94958 | H64: 1024 | I64: =A64*B64 -> 128 | J64: =C64*D64 -> 8 | K64: =E64*F64 -> 1 | L64: =G64 -> 17.94958
A65: 128 | B65: 1 | C65: 1 | D65: 1 | E65: 1 | F65: 8 | G65: 38.028045 | H65: 1024 | I65: =A65*B65 -> 128 | J65: =C65*D65 -> 1 | K65: =E65*F65 -> 8 | L65: =G65 -> 38.028045
A66: 1 | B66: 1 | C66: 1 | D66: 8 | E66: 128 | F66: 1 | G66: 21.30915 | H66: 1024 | I66: =A66*B66 -> 1 | J66: =C66*D66 -> 8 | K66: =E66*F66 -> 128 | L66: =G66 -> 21.30915
A67: 32 | B67: 1 | C67: 1 | D67: 8 | E67: 4 | F67: 1 | G67: 20.63063 | H67: 1024 | I67: =A67*B67 -> 32 | J67: =C67*D67 -> 8 | K67: =E67*F67 -> 4 | L67: =G67 -> 20.63063
A68: 16 | B68: 1 | C68: 1 | D68: 8 | E68: 8 | F68: 1 | G68: 21.051148 | H68: 1024 | I68: =A68*B68 -> 16 | J68: =C68*D68 -> 8 | K68: =E68*F68 -> 8 | L68: =G68 -> 21.051148
A69: 8 | B69: 1 | C69: 1 | D69: 8 | E69: 16 | F69: 1 | G69: 21.254376 | H69: 1024 | I69: =A69*B69 -> 8 | J69: =C69*D69 -> 8 | K69: =E69*F69 -> 16 | L69: =G69 -> 21.254376
A70: 4 | B70: 1 | C70: 1 | D70: 8 | E70: 32 | F70: 1 | G70: 21.341927 | H70: 1024 | I70: =A70*B70 -> 4 | J70: =C70*D70 -> 8 | K70: =E70*F70 -> 32 | L70: =G70 -> 21.341927
A71: 2 | B71: 1 | C71: 1 | D71: 8 | E71: 64 | F71: 1 | G71: 21.357576 | H71: 1024 | I71: =A71*B71 -> 2 | J71: =C71*D71 -> 8 | K71: =E71*F71 -> 64 | L71: =G71 -> 21.357576
...

Sheet H100-HBM
A2: Time spent (data traffic)
A3: T_mem (in sec) | B3: =MAX(H29/F20,I38/G20,J47/H20) -> 8.9265046e-05
A7: Application/Mapping specific parameters
A8: Assumptions
A9: Parameter | B9: Linear dimension of the compute block (N_x) | C9: # of computation points that we wish to parallelize | D9: #threads required as per the application | E9: # thread blocks | F9: # groups | G9: Bx | H9: By | I9: Bz | J9: halo_width
A10: use calculation or override with user input | B10: user input | C10: calculated | D10: calculated | E10: calculated | F10: calculated | G10: user input | H10: user input | I10: user input | J10: user input
A11: Value used in formula | B11: =IF(B10=Inputs!$C$1,B12,B13) -> 256 | C11: =IF(C10=Inputs!$C$1,C12,C13) -> 16777216 | D11: =IF(D10=Inputs!$C$1,D12,D13) -> 16777216 | E11: =IF(E10=Inputs!$C$1,E12,E13) -> 131072 | F11: =IF(F10=Inputs!$C$1,F12,F13) -> 14.222222 | G11: =IF(G10=Inputs!$C$1,G12,G13) -> 32 | H11: =IF(H10=Inputs!$C$1,H12,H13) -> 4 | I11: =IF(I10=Inputs!$C$1,I12,I13) -> 1 | J11: =IF(J10=Inputs!$C$1,J12,J13) -> 2
A12: user input value | B12: 256 | G12: 32 | H12: 4 | I12: 1 | J12: 2
A13: Calculated from more detail or defined earlier | B13: =B26 -> 0 | C13: =B11*B11*B11 -> 16777216 | D13: =C11 -> 16777216 | E13: =D11/D20 -> 131072 | F13: =E11/N20 -> 14.222222 | G13: =G26 -> 0 | H13: =H26 -> 0 | I13: =I26 -> 0 | J13: =J26 -> 0
A14: comments
A16: Hardware specs
A17: Assumptions
A18: Parameter | B18: Number of threads per SM | C18: Number of SMs | D18: # threads per block | E18: Clock rate (R) in GHz | F18: BW_SM (GB/s) | G18: BW_L2 (GB/s) | H18: BW_GM (GB/s) | I18: on-SM storage (KB) | J18: L2 cache size (KB) | K18: L2 cache-line size (B) | L18: occupancy | M18: # thread blocks per SM | N18: # thread blocks per group | O18: BW per SM (GB/s) | P18: SM cache-line size (B) | Q18: BW per L2 (GB/s)
A19: use calculation or override with user input | B19: user input | C19: user input | D19: user input | E19: user input | F19: calculated | G19: user input | H19: user input | I19: calculated | J19: user input | K19: user input | L19: user input | M19: calculated | N19: calculated | O19: calculated | P19: user input | Q19: user input
A20: Value used in formula | B20: =IF(B19=Inputs!$C$1,B21,B22) -> 2048 | C20: =IF(C19=Inputs!$C$1,C21,C22) -> 576 | D20: =IF(D19=Inputs!$C$1,D21,D22) -> 128 | E20: =IF(E19=Inputs!$C$1,E21,E22) -> 1.8 | F20: =IF(F19=Inputs!$C$1,F21,F22) -> 33730.56 | G20: =IF(G19=Inputs!$C$1,G21,G22) -> 13500 | H20: =IF(H19=Inputs!$C$1,H21,H22) -> 6451 | I20: =IF(I19=Inputs!$C$1,I21,I22) -> 64 | ... K20: =IF(K19=Inputs!$C$1,K21,K22) -> 64 | L20: 1 | M20: =IF(M19=Inputs!$C$1,M21,M22) -> 16 | N20: =IF(N19=Inputs!$C$1,N21,N22) -> 9216 | O20: =IF(O19=Inputs!$C$1,O21,O22) -> 58.56 | P20: =IF(P19=Inputs!$C$1,P21,P22) -> 64 | Q20: =IF(Q19=Inputs!$C$1,Q21,Q22) -> 8
A21: user input value | B21: 2048 | C21: 576 | D21: 128 | E21: 1.8 | G21: 13500 | H21: 6451 | I21: 256 | J21: 61440 | K21: 64 | L21: 1 | O21: 234 | P21: 64 | Q21: 8
A22: Calculated from more detail or defined earlier | B22: 0 | C22: 0 | D22: 0 | E22: 0 | F22: =O20*C20 -> 33730.56 | G22: =Q20*C20 -> 4608 | H22: 0 | I22: =IF(C20=144,256,64) -> 64 | J22: 0 | K22: 0 | L22: 1 | M22: =B20/D20 -> 16 | N22: =M20*C20 -> 9216 | O22: =IF(C20=144,234.24,58.56) -> 58.56 | P22: 0 | Q22: 0
A23: comments
A25: On SM to thread private registers
A26: Assumptions
A27: Parameter | B27: Precesion (byte) | C27: Number of threads per SM | D27: number of loads per thread from the on-SM storage to registers | E27: number of corresponding stores per thread | F27: no of algined (with L1 cache-line of 128B) loads | G27: no of miss-algined loads | H27: traffic volume between SM and registers (V_SM) in GB | I27: time
A28: use calculation or override with user input | B28: user input | C28: calculated | D28: calculated | E28: user input | F28: user input | G28: user input | H28: calculated | I28: calculated
A29: Value used in formula | B29: =IF(B28=Inputs!$C$1,B30,B31) -> 16 | C29: =IF(C28=Inputs!$C$1,C30,C31) -> 2048 | D29: =IF(D28=Inputs!$C$1,D30,D31) -> 9 | E29: =IF(E28=Inputs!$C$1,E30,E31) -> 1 | F29: =IF(F28=Inputs!$C$1,F30,F31) -> 5 | G29: =IF(G28=Inputs!$C$1,G30,G31) -> 2 | H29: =IF(H28=Inputs!$C$1,H30,H31) -> 2.5 | I29: =IF(I28=Inputs!$C$1,I30,I31) -> 7.4116765e-05
A30: user input value | B30: 16 | D30: 50 | E30: 1 | F30: 5 | G30: 2
A31: Calculated from more detail or defined earlier | B31: 0 | C31: =B20 -> 2048 | D31: =F29+2*G29 -> 9 | E31: 0 | F31: 0 | G31: 0 | H31: =C11*B29*(D29+E29)/1024^3 -> 2.5 | I31: =H29/F20 -> 7.4116765e-05
A32: comments
A34: L2 cache to On SM storage
A35: Assumptions
